Workbook

Sheet Summary
A1: Underwriting Summary
A2: All values flow from the other sheets via cross-sheet formulas. Fictitious data for parser testing.
A4: Property | B4: =Assumptions!B3 -> Example Gardens Apartments (fictitious)
A5: Units | B5: =Assumptions!B5 -> 48
A6: Occupied Units | B6: =COUNTIF('Rent Roll'!H4:H51,"Current") -> 44
A7: Physical Occupancy | B7: =B6/B5 -> 0.91666667
A8: In-Place Monthly Rent | B8: ='Rent Roll'!F52 -> 77630
A9: Effective Gross Income | B9: ='Operating Statement'!B6 -> 911378.4
A10: Total Operating Expenses | B10: ='Operating Statement'!B18 -> 471520.14
A11: Net Operating Income | B11: ='Operating Statement'!B19 -> 439858.26
A12: Annual Debt Service | B12: ='Debt Service'!B7 -> 328977.7
A13: DSCR | B13: ='Debt Service'!B9 -> 1.3370458
A14: LTV | B14: ='Debt Service'!B10 -> 0.65
A15: Going-in Cap Rate | B15: ='Debt Service'!B11 -> 0.064212885

Sheet Assumptions
A1: Underwriting Assumptions
A3: Property | B3: Example Gardens Apartments (fictitious)
A4: Address | B4: 123 Example St, Anytown, NY 12345
A5: Units | B5: 48
A6: Purchase Price | B6: 6850000
A7: Loan Amount | B7: 4452500
A8: Interest Rate | B8: 0.0625
A9: Amortization (years) | B9: 30
A10: Loan Term (years) | B10: 10
A11: Vacancy & Credit Loss | B11: 0.06
A12: Management Fee (% of EGI) | B12: 0.04
A13: Other Income per Unit per Month | B13: 62
A14: Replacement Reserve per Unit | B14: 300
A15: Exit Cap Rate | B15: 0.0575

Sheet Rent Roll
A1: Rent Roll as of 3/31/2026
A3: Unit | B3: Type | C3: Sq Ft | D3: Tenant | E3: Lease End | F3: Monthly Rent | G3: Annual Rent | H3: Status
A4: A-101 | B4: 2BR/1BA | C4: 850 | D4: Pat Placeholder | E4: 06/31/2026 | F4: 1700 | G4: =F4*12 -> 20400 | H4: Current
A5: A-102 | B5: 3BR/2BA | C5: 1150 | D5: Jordan Dummy | E5: 10/30/2026 | F5: 2250 | G5: =F5*12 -> 27000 | H5: Current
A6: A-103 | B6: 1BR/1BA | C6: 650 | D6: John Sample | E6: 12/28/2027 | F6: 1400 | G6: =F6*12 -> 16800 | H6: Current
A7: A-104 | B7: 2BR/2BA | C7: 950 | D7: Casey Example | E7: 05/31/2026 | F7: 1925 | G7: =F7*12 -> 23100 | H7: Current
A8: A-105 | B8: 3BR/2BA | C8: 1150 | D8: Sam Specimen | E8: 10/28/2026 | F8: 2350 | G8: =F8*12 -> 28200 | H8: Current
A9: A-106 | B9: Studio | C9: 480 | D9: Taylor Testcase | E9: 02/31/2027 | F9: 1145 | G9: =F9*12 -> 13740 | H9: Current
A10: A-107 | B10: 2BR/1BA | C10: 850 | D10: VACANT | F10: 0 | G10: =F10*12 -> 0 | H10: Vacant
A11: A-108 | B11: 2BR/2BA | C11: 950 | D11: Jordan Dummy | E11: 02/30/2026 | F11: 1825 | G11: =F11*12 -> 21900 | H11: Current
A12: A-201 | B12: 3BR/2BA | C12: 1150 | D12: Jordan Dummy | E12: 09/30/2027 | F12: 2250 | G12: =F12*12 -> 27000 | H12: Current
A13: A-202 | B13: 2BR/1BA | C13: 850 | D13: John Sample | E13: 09/31/2026 | F13: 1725 | G13: =F13*12 -> 20700 | H13: Current
A14: A-203 | B14: 1BR/1BA | C14: 650 | D14: Pat Placeholder | E14: 11/30/2026 | F14: 1350 | G14: =F14*12 -> 16200 | H14: Current
A15: A-204 | B15: 2BR/1BA | C15: 850 | D15: Jordan Dummy | E15: 02/31/2027 | F15: 1675 | G15: =F15*12 -> 20100 | H15: Current
A16: A-205 | B16: 3BR/2BA | C16: 1150 | D16: Sam Specimen | E16: 10/31/2027 | F16: 2275 | G16: =F16*12 -> 27300 | H16: Current
A17: A-206 | B17: Studio | C17: 480 | D17: Jane Sample | E17: 06/30/2027 | F17: 1195 | G17: =F17*12 -> 14340 | H17: Current
A18: A-207 | B18: 2BR/1BA | C18: 850 | D18: Jordan Dummy | E18: 01/30/2027 | F18: 1675 | G18: =F18*12 -> 20100 | H18: Current
A19: A-208 | B19: 2BR/2BA | C19: 950 | D19: Alex Example | E19: 03/30/2026 | F19: 1850 | G19: =F19*12 -> 22200 | H19: Current
A20: A-301 | B20: 2BR/2BA | C20: 950 | D20: Alex Example | E20: 09/31/2027 | F20: 1850 | G20: =F20*12 -> 22200 | H20: Current
A21: A-302 | B21: Studio | C21: 480 | D21: John Sample | E21: 06/28/2027 | F21: 1120 | G21: =F21*12 -> 13440 | H21: Current
A22: A-303 | B22: Studio | C22: 480 | D22: Alex Example | E22: 11/28/2027 | F22: 1095 | G22: =F22*12 -> 13140 | H22: Current
... A25: A-306 | B25: 2BR/2BA | C25: 950 | D25: Jordan Dummy | E25: 08/30/2026 | F25: 1925 | G25: =F25*12 -> 23100 | H25: Current
A26: A-307 | B26: 2BR/2BA | C26: 950 | D26: VACANT | F26: 0 | G26: =F26*12 -> 0 | H26: Vacant
A27: A-308 | B27: 2BR/2BA | C27: 950 | D27: Jane Sample | E27: 03/31/2026 | F27: 1825 | G27: =F27*12 -> 21900 | H27: Current
A28: B-101 | B28: 1BR/1BA | C28: 650 | D28: Taylor Testcase | E28: 05/28/2027 | F28: 1425 | G28: =F28*12 -> 17100 | H28: Current
A29: B-102 | B29: 3BR/2BA | C29: 1150 | D29: VACANT | F29: 0 | G29: =F29*12 -> 0 | H29: Vacant
A30: B-103 | B30: Studio | C30: 480 | D30: Taylor Testcase | E30: 04/31/2027 | F30: 1170 | G30: =F30*12 -> 14040 | H30: Current
A31: B-104 | B31: 2BR/1BA | C31: 850 | D31: VACANT | F31: 0 | G31: =F31*12 -> 0 | H31: Vacant
A32: B-105 | B32: 2BR/2BA | C32: 950 | D32: Taylor Testcase | E32: 07/30/2027 | F32: 1875 | G32: =F32*12 -> 22500 | H32: Current
A33: B-106 | B33: 2BR/1BA | C33: 850 | D33: Casey Example | E33: 11/31/2026 | F33: 1750 | G33: =F33*12 -> 21000 | H33: Current
A34: B-107 | B34: 3BR/2BA | C34: 1150 | D34: John Sample | E34: 08/30/2027 | F34: 2275 | G34: =F34*12 -> 27300 | H34: Current
A35: B-108 | B35: 1BR/1BA | C35: 650 | D35: Jordan Dummy | E35: 08/30/2027 | F35: 1425 | G35: =F35*12 -> 17100 | H35: Current
A36: B-201 | B36: 3BR/2BA | C36: 1150 | D36: Alex Example | E36: 11/30/2027 | F36: 2250 | G36: =F36*12 -> 27000 | H36: Current
A37: B-202 | B37: 3BR/2BA | C37: 1150 | D37: Alex Example | E37: 03/28/2027 | F37: 2300 | G37: =F37*12 -> 27600 | H37: Current
A38: B-203 | B38: Studio | C38: 480 | D38: Alex Example | E38: 03/30/2027 | F38: 1145 | G38: =F38*12 -> 13740 | H38: Current
A39: B-204 | B39: 2BR/2BA | C39: 950 | D39: Pat Placeholder | E39: 02/30/2026 | F39: 1825 | G39: =F39*12 -> 21900 | H39: Current
A40: B-205 | B40: Studio | C40: 480 | D40: Alex Example | E40: 06/31/2027 | F40: 1120 | G40: =F40*12 -> 13440 | H40: Current
A41: B-206 | B41: 3BR/2BA | C41: 1150 | D41: Casey Example | E41: 09/30/2026 | F41: 2300 | G41: =F41*12 -> 27600 | H41: Current
A42: B-207 | B42: 2BR/1BA | C42: 850 | D42: Alex Example | E42: 04/28/2026 | F42: 1675 | G42: =F42*12 -> 20100 | H42: Current
A43: B-208 | B43: Studio | C43: 480 | D43: Sam Specimen | E43: 11/31/2026 | F43: 1095 | G43: =F43*12 -> 13140 | H43: Current
...

Sheet Operating Statement
A1: Pro Forma Operating Statement (Year 1)
A3: Gross Potential Rent (in-place, annualized) | B3: ='Rent Roll'!G52 -> 931560
A4: Less: Vacancy & Credit Loss | B4: =-B3*Assumptions!B11 -> -55893.6
A5: Other Income | B5: =Assumptions!B5*Assumptions!B13*12 -> 35712
A6: Effective Gross Income | B6: =SUM(B3:B5) -> 911378.4
A8: Real Estate Taxes | B8: 118400
A9: Insurance | B9: 41250
A10: Utilities | B10: 52780
A11: Repairs & Maintenance | B11: 61940
A12: Contract Services | B12: 23600
A13: Payroll | B13: 98500
A14: Management Fee | B14: =B6*Assumptions!B12 -> 36455.136
A15: General & Administrative | B15: 14320
A16: Marketing | B16: 9875
A17: Replacement Reserves | B17: =Assumptions!B5*Assumptions!B14 -> 14400
A18: Total Operating Expenses | B18: =SUM(B8:B17) -> 471520.14
A19: Net Operating Income | B19: =B6-B18 -> 439858.26
A20: Expense Ratio | B20: =B18/B6 -> 0.51737032

Sheet Debt Service
A1: Debt Service & Returns
A3: Loan Amount | B3: =Assumptions!B7 -> 4452500
A4: Interest Rate | B4: =Assumptions!B8 -> 0.0625
A5: Amortization (months) | B5: =Assumptions!B9*12 -> 360
A6: Monthly Payment | B6: =-PMT(B4/12,B5,B3) -> 27414.808
A7: Annual Debt Service | B7: =B6*12 -> 328977.7
A8: Net Operating Income | B8: ='Operating Statement'!B19 -> 439858.26
A9: DSCR | B9: =B8/B7 -> 1.3370458
A10: LTV | B10: =B3/Assumptions!B6 -> 0.65
A11: Going-in Cap Rate | B11: =B8/Assumptions!B6 -> 0.064212885
A12: Debt Yield | B12: =B8/B3 -> 0.098789054
A13: Cash Flow After Debt Service | B13: =B8-B7 -> 110880.56
